Workbook

Sheet SUN REALTY-MEM COLL
C1: GRAVITAS
C4: CALCULATION For the month of NOV-25
C6: SHOP MEMBERS COLLECTION BEFORE BU
C7: Flat No. | D7: Name of Owner | E7: CR SIDE | F7: LAND PORTION (One Third) | G7: TAXABLE VALUE (Two Third) | H7: REFUND OF SAME PEROID( WITH GST) | I7: REFUND WITHOUT GST | J7: Receipt of Maintenance Expence | K7: Receipt of refundable /MAINTENANCE Deposit | L7: Payment of refundable /MAINTENANCE Deposit | M7: Refundable deposit repayment | N7: Receipt Stamp Duty /JV (Cr) | O7: Payment Stamp Duty /JV (Dr) | P7: Receipt Registration Fees/JV (Cr) | Q7: Payment of Reg Fees/JV (Dr) | R7: SALES JOURNAL | S7: JV of AEC, AUDA, extra work | T7: Payment of stampduty on behalf of party | U7: Receipt of AEC, AUDA | V7: GST Reversal Entry due to E - Invoice | W7: Refundable Deposite income | X7: Cancellation income | Y7: Cheque Return | Z7: NET RECEIPT
E9: 0 | F9: =+E9/3 | G9: =+E9-F9 | Z9: =E9-P9-K9-J9-U9-N9
F10: =+E10/3 | G10: =+E10-F10 | I10: 0 | Q10: =+P10 | Y10: 0 | Z10: =E10-P10-K10-J10-U10-N10
B11: =+AA11 | F11: =+E11/3 | G11: =+E11-F11 | O11: =N11 | Q11: =+P11 | Z11: =E11-P11-K11-J11-U11-N11 | AA11: =Z11*6/100 | AB11: =+H11+I11+M11+Q11+R11+S11+T11+Y11
B12: =+AA12 | F12: =+E12/3 | G12: =+E12-F12 | Z12: =E12-P12-K12-J12-U12-N12 | AA12: =Z12*6/100 | AB12: =+H12+I12+M12+Q12+R12+S12+T12+Y12
B13: =+AA13 | Z13: =E13-P13-K13-J13-U13-N13 | AA13: =Z13*6/100 | AB13: =+H13+I13+M13+Q13+R13+S13+T13+Y13
B14: =+AA14 | F14: =+E14/3 | G14: =+E14-F14 | O14: =+N14 | Q14: =+P14 | Z14: =E14-P14-K14-J14-U14-N14 | AA14: =(Z14*6/100)+(J14*9/100) | AB14: =+H14+I14+M14+Q14+R14+S14+T14+Y14
B15: =+AA15 | F15: =+E15/3 | G15: =+E15-F15 | O15: 0 | Q15: =+P15 | Z15: =E15-P15-K15-J15-U15-N15 | AA15: =Z15*6/100 | AB15: =+H15+I15+M15+Q15+R15+S15+T15+Y15
B16: =+AA16 | F16: =+E16/3 | G16: =+E16-F16 | O16: =+N16 | Q16: 0 | Z16: =E16-P16-K16-J16-U16-N16 | AA16: =Z16*6/100 | AB16: =+H16+I16+M16+Q16+R16+S16+T16+Y16
B17: =+AA17 | F17: =+E17/3 | G17: =+E17-F17 | O17: =+N17 | Q17: 0 | Z17: =E17-P17-K17-J17-U17-N17 | AA17: =Z17*6/100 | AB17: =+H17+I17+M17+Q17+R17+S17+T17+Y17
B18: =+AA18 | F18: =+E18/3 | G18: =+E18-F18 | O18: =+N18 | Z18: =E18-P18-K18-J18-U18-N18 | AA18: =Z18*6/100 | AB18: =+H18+I18+M18+Q18+R18+S18+T18+Y18
B19: =+AA19 | F19: =+E19/3 | G19: =+E19-F19 | Z19: =E19-P19-K19-J19-U19-N19 | AA19: =Z19*6/100 | AB19: =+H19+I19+M19+Q19+R19+S19+T19+Y19
B20: =+AA20 | F20: =+E20/3 | G20: =+E20-F20 | O20: =+N20 | Q20: =+P20 | Z20: =E20-P20-K20-J20-U20-N20 | AA20: =Z20*6/100 | AB20: =+H20+I20+M20+Q20+R20+S20+T20+Y20
C21: Total | E21: =SUM(E9:E20) | F21: =SUM(F9:F20) | G21: =SUM(G9:G20) | H21: =SUM(H9:H20) | I21: =SUM(I9:I20) | J21: =SUM(J9:J20) | K21: =SUM(K9:K20) | M21: =SUM(M9:M20) | N21: =SUM(N9:N20) | O21: =SUM(O9:O20) | P21: =SUM(P9:P20) | Q21: =SUM(Q9:Q20) | R21: =SUM(R9:R20) | S21: =SUM(S9:S20) | T21: =SUM(T9:T20) | ... Z21: =SUM(Z9:Z20)
Z22: =Y21+T21+S21+R21+Q21+M21+I21+H21
C23: AFTER BU
C24: SHOP MEMBERS COLLECTION AFTER BU
C25: Flat No. | D25: Name of Owner | E25: CR SIDE | F25: LAND PORTION (One Third) | G25: TAXABLE VALUE (Two Third) | H25: REFUND OF SAME PEROID ( WITH GST) | I25: REFUND OF PREVIOUS PEROID ( WITHOUT GST) | J25: Receipt of Maintenance Expence | K25: Receipt of refundable /MAINTENANCE Deposit | L25: Payment of refundable /MAINTENANCE Deposit | M25: Maintenance deposit JV/(DR) | N25: Receipt Stamp Duty /JV (Cr) | O25: Payment Stamp Duty /JV (Dr) | P25: Receipt Registration Fees/JV (Cr) | Q25: Payment of Reg Fees/JV (Dr) | R25: SALES JOURNAL/SALES DEED | S25: JV of AEC, AUDA, extra work | T25: Payment of stampduty on behalf of party | U25: Receipt of AEC, AUDA | V25: GST Reversal Entry due to E - Invoice | W25: Refundable Deposite income | X25: Cancellation income | Y25: Cheque Return | Z25: NET RECEIPT
O27: =N27 | R27: 0 | S27: 0 | T27: 0 | U27: 0 | Z27: =E27-P27-K27-J27-U27-N27
F28: 0 | G28: 0 | O28: =N28 | R28: 0 | Z28: =E28-P28-K28-J28-U28-N28
O29: =N29 | R29: 0 | Z29: =E29-P29-K29-J29-U29-N29
O30: =N30 | R30: 0 | Z30: =E30-P30-K30-J30-U30-N30
O31: =N31 | Z31: =E31-P31-K31-J31-U31-N31
R32: 0 | Z32: =E32-P32-K32-J32-U32-N32
R33: 0
Z34: =E34-P34-K34-J34-U34-N34
L35: =K35 | Q35: =P35 | Z35: =E35-P35-K35-J35-U35-N35
F36: 0 | G36: 0 | O36: =N36 | Q36: =P36 | Z36: =E36-P36-K36-J36-U36-N36
F37: 0 | G37: 0 | O37: =N37 | Q37: =P37 | Z37: =E37-P37-K37-J37-U37-N37
F38: 0 | G38: 0 | O38: =N38 | Q38: =P38 | Z38: =E38-P38-K38-J38-U38-N38
F39: 0 | G39: 0 | Q39: =P39 | Z39: =E39-P39-K39-J39-U39-N39
F40: 0 | G40: 0 | J40: 0 | O40: =N40 | Z40: =E40-P40-K40-J40-U40-N40 | AB40: =+H40+I40+M40+Q40+R40+S40+T40+Y40
Z41: =E41-P41-K41-J41-U41-N41 | AB41: =+H41+I41+M41+Q41+R41+S41+T41+Y41
Z43: =E43-P43-K43-J43-U43-N43
H44: 0 | Z44: =E44-P44-K44-J44-U44-N44
Z45: =E45-P45-K45-J45-U45-N45
Z46: =E46-P46-K46-J46-U46-N46
...

Sheet SUN REALTY-CALC
A1: Sun Realty
A4: GST PAYABLE ON COMMERCIAL CONSTRUCTION FOR THE MONTH OF AUG-26
A6: Supply | B6: AMOUNT | C6: LAND VALUE (1/3) | D6: TAXABLE VALUE (2/3) | E6: RATE | F6: CGST @ 9% | G6: SGST@ 9% | H6: TOTAL
A8: COMMERCIAL CONSTRUCTION SERVICE | B8: ='SUN REALTY-MEM COLL'!Z21 | C8: =B8/3 | D8: =B8-C8 | E8: 0.18 | F8: =+D8*9% | G8: =+D8*9% | H8: =+F8+G8
A9: Refundable Deposite Income (B2C) | B9: =+'SUN REALTY-MEM COLL'!W21+'SUN REALTY-MEM COLL'!W49 | D9: =B9*100/118 | E9: 0.18 | F9: =+D9*9% | G9: =+D9*9% | H9: =+F9+G9
A10: B2B E- Invoice Effect In Payable | F10: 0 | G10: 0
A11: Less : Refund | B11: =-'SUN REALTY-MEM COLL'!H21 | C11: =+B11/3 | D11: =+B11-C11 | E11: 0.18 | F11: =+D11*9% | G11: =+D11*9% | H11: =+F11+G11
A12: ADD: Maintenance Expence | B12: ='SUN REALTY-MEM COLL'!J21+'SUN REALTY-MEM COLL'!J49 | E12: 0.18 | F12: =B12*9/100 | G12: =F12 | H12: =+F12+G12
A13: ADD: Receipt of AEC, AUDA | B13: ='SUN REALTY-MEM COLL'!U21 | C13: =B13/3 | D13: =B13-C13 | E13: 0.18 | F13: =+D13*9% | G13: =+D13*9% | H13: =+F13+G13
A15: LESS:- Entry of Receipt deleted Back dated hence excess payment shows
D16: 0 | E16: 0.18 | F16: =B16*9/100 | G16: =F16 | H16: =+F16+G16
B17: 0 | C17: =+B17/3 | D17: =B17-C17 | E17: 0.18 | F17: =+D17*9% | G17: =+D17*9% | H17: =+F17+G17
C18: =+B18/3 | D18: =+B18-C18 | E18: 0.18 | F18: =+D18*9% | G18: =+D18*9% | H18: =+F18+G18
A19: TOTAL | B19: =SUM(B8:B18) | C19: =SUM(C8:C18) | D19: =SUM(D8:D18) | F19: =SUM(F8:F18) | G19: =SUM(G8:G18) | H19: =SUM(H8:H18)
A20: B2C
A21: Cancellation Income | B21: 0 | C21: 0 | E21: 0.18 | F21: =+D21*9% | G21: =+D21*9% | H21: =+F21+G21
E22: 0.18 | F22: =+D22*9% | G22: =+D22*9% | H22: =+F22+G22
A23: Advance adjusted for same | D23: =-B23*2/3 | E23: 0.18 | F23: =+D23*9% | G23: =+D23*9% | H23: =+F23+G23
A24: Extra work income (2/3portion only) | B24: =+'SUN REALTY-MEM COLL'!S21 | D24: =B24*2/3 | E24: 0.18 | F24: =+D24*9% | G24: =+D24*9% | H24: =+F24+G24
A25: Advance adjusted for same | B25: =-B24 | D25: =B25*2/3 | E25: 0.18 | F25: =+D25*9% | G25: =+D25*9% | H25: =+F25+G25
A26: COMMERCIAL CONSTRUCTION SERVICE (AFTER BU) | B26: =+'SUN REALTY-MEM COLL'!R49+'SUN REALTY-MEM COLL'!S49
A27: COMMERCIAL CONSTRUCTION SERVICE (AFTER BU) BACK DATED ENTRY in Jan-26 (838, Zahabiya After Bu) | B27: 0
A29: TOTAL | B29: =SUM(B22:B27)+B19 | C29: =SUM(C22:C27)+C19 | D29: =SUM(D22:D27)+D19 | F29: =SUM(F22:F27)+F19 | G29: =SUM(G22:G27)+G19 | H29: =SUM(H22:H27)
A30: B2C SALE & Advance adjustment (as per sale deed sheet) | E30: 0.18 | F30: =+D30*9% | G30: =+D30*9% | H30: =+F30+G30
A33: Supply | B33: GSTIN | D33: AMOUNT | E33: RATE | F33: CGST | G33: SGST | H33: TOTAL
A36: Rent income-Meglyn Technologies Pvt Ltd (SAC-)] ( To be Confirm is there any income ) | B36: 24AAJCM9952F1Z6 | E36: 0.18 | F36: =+D36*E36/2 | G36: =+D36*E36/2 | H36: =+SUM(F36:G36)
A38: TOTAL | D38: =+SUM(D35:D37) | F38: =+SUM(F35:F37) | G38: =+SUM(G35:G37) | H38: =+SUM(H35:H37)
A41: GST PAYABLE UNDER RCM FOR THE MONTH OF AUG-26
A42: .
A43: Service | B43: AMOUNT | C43: RATE | D43: CGST | E43: SGST | F43: TOTAL
A45: SUN GRAVITAS
A46: Advocate fees | B46: 0 | C46: 0.18 | D46: =+B46*9/100 | E46: =+D46 | F46: =+D46+E46
A47: Carting and Transportation (Gayatri Sales Corp) | C47: 0.05 | D47: =+B47*0.025 | E47: =+D47 | F47: =+D47+E47
A48: Security Services | C48: 0.18 | D48: =+B48*9% | E48: =+B48*9% | F48: =SUM(D48:E48)
A49: Sponsharship Services | C49: 0.18 | D49: =+B49*9% | E49: =+B49*9% | F49: =SUM(D49:E49)
A51: SUN OFFICE
A52: Freight Charges(Gayatri Sales Corporation) | C52: 0.05 | D52: =+B52*2.5/100 | E52: =+D52 | F52: =+D52+E52
A53: Security Expense | B53: 0 | C53: 0.18 | D53: =+B53*9/100 | E53: =+D53 | F53: =+D53+E53
A55: TOTAL | B55: =SUM(B45:B54) | D55: =SUM(D45:D54) | E55: =SUM(E45:E54) | F55: =SUM(F45:F54)
A57: INPUT TAX CREDIT FOR THE MONTH OF AUG-26
...

Sheet SUN REALTY ATMOS-MEMBERS COLL
B1: Sun Realty
B4: CALCULATION For the month of AUG-26
B6: MEMBERS COLLECTION
B7: Flat No | C7: Name of Owner | D7: CR SIDE | E7: Receipt of Registration Fees/JV (Cr) | F7: Payment of Reg Fees on Behalf of Client / JV (Dr) | G7: Receipt of stamp/ registartion duty/JV (Cr) | H7: Payment of stamp duty on Behalf of Client / JV (Dr) | I7: REFUND OF SAME PEROID | J7: REFUNDABLE DEPOSIT | K7: REFUNDABLE DEPOSIT JV(Dr.) | L7: REFUND WITHOUT GST | M7: Cheque Return Amount | N7: Sale Deed JV | O7: PLC JV | P7: PLC Income | Q7: AEC,AUDA JV | R7: KASAR | S7: Loan transfer to new person ( credit side) | T7: Loan transfer from old person ( Debit side) | U7: GST PAID @1% INSTEAD OF 18% | V7: NET RECEIPT | W7: GST
F8: =+E8 | H8: =+G8 | O8: 0 | P8: 0 | Q8: 0 | V8: =D8-E8-G8-J8-U8-R8-P8 | W8: =V8*0.5/100
F9: =E9 | H9: =G9 | K9: =J9 | V9: =D9-E9-G9-J9-U9-R9-P9 | W9: =V9*0.5/100
F10: =E10 | H10: =G10 | K10: =J10 | V10: =D10-E10-G10-J10-U10-R10-P10 | W10: =V10*0.5/100
F11: =E11 | H11: =G11 | K11: =J11 | V11: =D11-E11-G11-J11-U11-R11-P11 | W11: =V11*0.5/100
F12: =E12 | H12: =G12 | K12: =J12 | V12: =D12-E12-G12-J12-U12-R12-P12 | W12: =V12*0.5/100
F13: =E13 | H13: =G13 | K13: =J13 | V13: =D13-E13-G13-J13-U13-R13-P13 | W13: =V13*0.5/100
F14: =E14 | H14: =G14 | K14: =J14 | V14: =D14-E14-G14-J14-U14-R14-P14 | W14: =V14*0.5/100
F15: =E15 | H15: =G15 | K15: =J15 | V15: =D15-E15-G15-J15-U15-R15-P15 | W15: =V15*0.5/100
F16: =+E16 | H16: =G16 | K16: =J16 | V16: =D16-E16-G16-J16-U16-R16-P16 | W16: =V16*0.5/100
F17: =+E17 | H17: =G17 | K17: =J17 | V17: =D17-E17-G17-J17-U17-R17-P17 | W17: =V17*0.5/100
F18: =E18 | H18: 0 | K18: =J18 | V18: =D18-E18-G18-J18-U18-R18-P18 | W18: =V18*0.5/100
F19: =E19 | H19: =G19 | K19: =J19 | V19: =D19-E19-G19-J19-U19-R19-P19 | W19: =V19*0.5/100
F20: =E20 | H20: =G20 | K20: =J20 | V20: =D20-E20-G20-J20-U20-R20-P20 | W20: =V20*0.5/100 | AA20: =2553+26+163
F21: =E21 | H21: =G21 | K21: =J21 | V21: =D21-E21-G21-J21-U21-R21-P21 | W21: =V21*0.5/100
F22: =E22 | H22: =G22 | K22: =J22 | V22: =D22-E22-G22-J22-U22-R22-P22 | W22: =V22*0.5/100
F23: =E23 | H23: =G23 | K23: =J23 | V23: =D23-E23-G23-J23-U23-R23-P23 | W23: =V23*0.5/100
F24: =E24 | H24: =G24 | K24: =J24 | V24: =D24-E24-G24-J24-U24-R24-P24 | W24: =V24*0.5/100
F25: =E25 | H25: =G25 | V25: =D25-E25-G25-J25-U25-R25-P25 | W25: =V25*0.5/100
F26: =E26 | H26: =G26 | K26: =J26 | V26: =D26-E26-G26-J26-U26-R26-P26 | W26: =V26*0.5/100
F27: =E27 | H27: =G27 | K27: =J27 | V27: =D27-E27-G27-J27-U27-R27-P27 | W27: =V27*0.5/100
F28: =E28 | H28: =G28 | K28: =J28 | V28: =D28-E28-G28-J28-U28-R28-P28 | W28: =V28*0.5/100
F29: =E29 | H29: =G29 | K29: =J29 | V29: =D29-E29-G29-J29-U29-R29-P29 | W29: =V29*0.5/100 | X29: =IFERROR(VLOOKUP(C29,DATA!$U$2:$V$32,2,FALSE),0) | Y29: =+X29+G29 | Z29: =-Y29
F30: =E30 | H30: =G30 | K30: =J30 | V30: =D30-E30-G30-J30-U30-R30-P30 | W30: =V30*0.5/100 | X30: =IFERROR(VLOOKUP(C30,DATA!$U$2:$V$32,2,FALSE),0) | Y30: =+X30+G30 | Z30: =-Y30 | AD30: =138+821
F31: =E31 | H31: =G31 | K31: =J31 | V31: =D31-E31-G31-J31-U31-R31-P31 | W31: =V31*0.5/100 | X31: =IFERROR(VLOOKUP(C31,DATA!$U$2:$V$32,2,FALSE),0) | Y31: =+X31+G31 | Z31: =-Y31
F32: =E32 | H32: =G32 | K32: =J32 | V32: =D32-E32-G32-J32-U32-R32-P32 | W32: =V32*0.5/100 | X32: =IFERROR(VLOOKUP(C32,DATA!$U$2:$V$32,2,FALSE),0) | Y32: =+X32+G32 | Z32: =-Y32
F33: =E33 | H33: =G33 | K33: =J33 | V33: =D33-E33-G33-J33-U33-R33-P33 | W33: =V33*0.5/100 | X33: =IFERROR(VLOOKUP(C33,DATA!$U$2:$V$32,2,FALSE),0) | Y33: =+X33+G33 | Z33: =-Y33
F34: =E34 | H34: =G34 | V34: =D34-E34-G34-J34-U34-R34-P34 | W34: =V34*0.5/100 | X34: =IFERROR(VLOOKUP(C34,DATA!$U$2:$V$32,2,FALSE),0) | Y34: =+X34+G34 | Z34: =-Y34
F35: =E35 | H35: =G35 | K35: =J35 | V35: =D35-E35-G35-J35-U35-R35-P35 | W35: =V35*0.5/100 | X35: =IFERROR(VLOOKUP(C35,DATA!$U$2:$V$32,2,FALSE),0) | Y35: =+X35+G35 | Z35: =-Y35
F36: =E36 | H36: =G36 | K36: =J36 | V36: =D36-E36-G36-J36-U36-R36-P36 | W36: =V36*0.5/100
F37: =E37 | H37: =G37 | K37: =J37 | V37: =D37-E37-G37-J37-U37-R37-P37 | W37: =V37*0.5/100 | X37: =IFERROR(VLOOKUP(C37,DATA!$U$2:$V$32,2,FALSE),0) | Y37: =+X37+G37 | Z37: =-Y37
F38: =E38 | H38: =G38 | K38: =J38 | V38: =D38-E38-G38-J38-U38-R38-P38 | W38: =V38*0.5/100
F39: =E39 | H39: =G39 | K39: =J39 | V39: =D39-E39-G39-J39-U39-R39-P39 | W39: =V39*0.5/100
F40: =E40 | H40: =G40 | K40: =J40 | V40: =D40-E40-G40-J40-U40-R40-P40 | W40: =V40*0.5/100
F41: =E41 | H41: =G41 | K41: =J41 | V41: =D41-E41-G41-J41-U41-R41-P41 | W41: =V41*0.5/100
F42: =E42 | H42: =G42 | K42: =J42 | V42: =D42-E42-G42-J42-U42-R42-P42 | W42: =V42*0.5/100
F43: =E43 | H43: =G43 | K43: =J43 | V43: =D43-E43-G43-J43-U43-R43-P43 | W43: =V43*0.5/100 | X43: =IFERROR(VLOOKUP(C43,DATA!$U$2:$V$32,2,FALSE),0) | Y43: =+X43+G43 | Z43: =-Y43
...

Sheet DATA
B1: DEPOSIT | C1: RS | F1: regis | O1: Reg Fees Axis | R1: Stamp Fees Axis | U1: Reg Fees JV
B2: G-101, Darji Amit Gunvantbhai | C2: 30300 | F2: NAME | G2: DR | H2: CR | I2: NET | K2: A-1102,Dharman Gopalkumar Bhatt | L2: 930692 | O2: I-804,Anish Mahendra Bhatt & Maya A.Bhatt | P2: 32400 | R2: I-804,Anish Mahendra Bhatt & Maya A.Bhatt | S2: 148600 | U2: I-401, Sumara Chitra | V2: 1714.75
B3: G-101, Darji Amit Gunvantbhai | C3: 50000 | F3: E-1104, Priyanka Yadav, Pradeep Yadav | G3: 0 | H3: 171744 | I3: 171744 | K3: A-1301, Aniruddha Dutta | L3: 42100 | O3: A-503; Kantibhai D.Chudasama | P3: 42284 | R3: A-503; Kantibhai D.Chudasama | S3: 197400 | U3: I-201,Ajitbhai Kathi | V3: 1714.75
B4: H/1302,Yogesh Harikrishna Ardeshna | C4: 43000 | F4: I-401, Sumara Chitra | G4: 1714.75 | H4: 0 | I4: -1714.75 | K4: A-1304, Palak Harshadkumar Popat | L4: 460310 | O4: K-501,Vivek Goad / Raksha Sharma | P4: 2200 | R4: K-501,Vivek Goad / Raksha Sharma | S4: 215000 | U4: I-901, Shivam Thakur | V4: 1714.75
B5: H/1302,Yogesh Harikrishna Ardeshna | C5: 50000 | F5: I-201,Ajitbhai Kathi | G5: 1714.75 | H5: 0 | I5: -1714.75 | K5: A-1404, Manisha Umang Chokshi & Raj U. Chokshi | L5: 445544 | O5: P-704; Vishal Rajabhai Barad | P5: 32000 | R5: P-704; Vishal Rajabhai Barad | S5: 149000 | U5: L-803, Haresh Zanzrukia | V5: 1714.75
B6: N-104, Shital Kalpeshbhai Ajmera | C6: 50000 | F6: I-901, Shivam Thakur | G6: 1714.75 | H6: 0 | I6: -1714.75 | K6: A/204,Vipul Mistry | L6: 33976 | O6: L-1002,Nilesh Bhalchandra Yeole | P6: 46000 | R6: L-1002,Nilesh Bhalchandra Yeole | S6: 217000 | U6: D-804, Neha Bhavin Shah / Bhavin Dipakbhai Shah | V6: 708.85
B7: N-104, Shital Kalpeshbhai Ajmera | C7: 139500 | F7: L-803, Haresh Zanzrukia | G7: 1714.75 | H7: 0 | I7: -1714.75 | K7: A-304,Bhoomin Anantbhai Raval / Divya Bhoomin Raval | L7: 396040 | O7: P-304; Rupal Vishal Barad | P7: 2200 | R7: P-304; Rupal Vishal Barad | S7: 149000 | U7: N-503, Yash Satwani / Kiran Satwani | V7: 708.85
B8: N-903, Krunal Pravinkumar Chudasma | C8: 45000 | F8: D-804, Neha Bhavin Shah / Bhavin Dipakbhai Shah | G8: 708.85 | H8: 0 | I8: -708.85 | K8: A-502, Brajesh Kumar / Shalini Bhardwaj | L8: 661480 | O8: P-101, Rahul Ranjan | P8: 36500 | R8: N-903, Krunal Pravinkumar Chudasma | S8: 211000 | U8: A-1404, Manisha Umang Chokshi & Raj U. Chokshi | V8: 1714.75
B9: N-903, Krunal Pravinkumar Chudasma | C9: 50000 | F9: N-503, Yash Satwani / Kiran Satwani | G9: 708.85 | H9: 168400 | I9: 167691.15 | K9: A-503; Kantibhai D.Chudasama | L9: 761074 | O9: G-104, Daksha Rajeshbhai Darji | P9: 32280 | R9: P-101, Rahul Ranjan | S9: 169000 | U9: B-903, Smita Bhavinkumar Dave | V9: 263667.7
B10: A/204,Vipul Mistry | C10: 50000 | F10: A-1404, Manisha Umang Chokshi & Raj U. Chokshi | G10: 1714.75 | H10: 0 | I10: -1714.75 | K10: A-604., Deepakkumar, Ruchika Arora | L10: 570121 | O10: O-502, Jay Rajeshkumar Shah | P10: 42000 | R10: G-104, Daksha Rajeshbhai Darji | S10: 146000 | U10: C-1303, Vikas Jain / Anamika Jain | V10: 228769.7
B11: A-1102,Dharman Gopalkumar Bhatt | C11: 50000 | F11: I-804,Anish Mahendra Bhatt & Maya A.Bhatt | G11: 0 | H11: 181000 | I11: 181000 | K11: A/701,Hemantkumar Ishwarlal Bhavsar | L11: 900098 | O11: D-401, Bhartiben Mukeshbhai Halari / Dhaval Halari | P11: 42000 | R11: O-502, Jay Rajeshkumar Shah | S11: 197000 | U11: C/1304,Chetnaben Vallabhbhai Bavariya | V11: 182907.7
B12: A-1301, Aniruddha Dutta | C12: 50000 | F12: A-503; Kantibhai D.Chudasama | G12: 0 | H12: 239684 | I12: 239684 | K12: A/702,Hemantkumar Ishvarlal Bhavsar | L12: 900098 | O12: O-403,Jayesh Mansukhbhai Solanki | P12: 37000 | R12: D-401, Bhartiben Mukeshbhai Halari / Dhaval Halari | S12: 197000 | U12: D-604, Kashyap Dave | V12: 205803.7
B13: A-1304, Palak Harshadkumar Popat | C13: 50000 | F13: K-501,Vivek Goad / Raksha Sharma | G13: 215332.7 | H13: 217200 | I13: 1867.3 | K13: A-801; Ishwar S. Dubey | L13: 3165100 | O13: D-301,Rajesh Vithaldas Chokshi | P13: 42000 | R13: O-403,Jayesh Mansukhbhai Solanki | S13: 172000 | U13: D-1403,Jay Adthakkar | V13: 186587.7
B14: A-502, Brajesh Kumar / Shalini Bhardwaj | C14: 50000 | F14: P-704; Vishal Rajabhai Barad | G14: 0 | H14: 181000 | I14: 181000 | K14: A-902, Puja Chudasama | L14: 37624 | O14: J-1003,Jagdish Pankajkumar Patel | P14: 45000 | R14: D-301,Rajesh Vithaldas Chokshi | S14: 194000 | U14: F-203, Kalpesh Rohit Contractor & Nency Contractor | V14: 174417.7
... B32: C-1303, Vikas Jain / Anamika Jain | C32: 50000 | F32: K-202,Chinjal Lalitkumar Modi | G32: 0 | H32: 208500 | I32: 208500 | K32: C/1304,Chetnaben Vallabhbhai Bavariya | L32: 36732 | O32: C-1103, Sima Jigar Desai /Jigar S.Desai | P32: 45000 | R32: C-1103, Sima Jigar Desai /Jigar S.Desai | S32: 211000 | U32: H/1302,Yogesh Harikrishna Ardeshna | V32: 200908.85
B33: C-603,Umesh Shishivandan Pandya | C33: 50000 | F33: G-1003, Parth Mathurbhai Dobariya | G33: 0 | H33: 194600 | I33: 194600 | K33: C-204, Parin Rakeshkumar Bodiwala | L33: 575674 | O33: A-604., Deepakkumar, Ruchika Arora | P33: 43000 | R33: A-604., Deepakkumar, Ruchika Arora | S33: 202000
B34: D/101, Parth Madaan | C34: 50000 | F34: K-403,Mahesh Madhukar Bharambe | G34: 0 | H34: 241500 | I34: 241500 | K34: C/502, Isha Nishant Bhavsar | L34: 592654 | O34: F-1003,Garima Rajawat & Jaisingh Sisodia | P34: 42000 | R34: F-1003,Garima Rajawat & Jaisingh Sisodia | S34: 198000
B35: D/102 Disha Bhagya Dave | C35: 50000 | F35: F-503, Sanjay Bhadra | G35: 0 | H35: 210666 | I35: 210666 | K35: C/503,Rajneesh Bakshi | L35: 341319 | O35: M/502 Javankiaben Koradiya, Naresh Koradiya | P35: 2200 | R35: M/502 Javankiaben Koradiya, Naresh Koradiya | S35: 169000
B36: D/1201 Shobhit Trapasiya | C36: 50000 | F36: F-801,Ashokkumar M.Sonagara | G36: 0 | H36: 138200 | I36: 138200 | K36: C-603,Umesh Shishivandan Pandya | L36: 617108 | O36: N-1103,Sumanta Bose | P36: 40000 | R36: N-1103,Sumanta Bose | S36: 187000
B37: D-1002, Kishorsinh Anopsinh Jadeja | C37: 50000 | F37: C-1003,Rahul Pandya | G37: 0 | H37: 217650 | I37: 217650 | K37: C/702 Taraben Vasantlal Jain, Jain Amrita | L37: 825410 | O37: F-204, Jaxnikumar Naik | P37: 30400 | R37: F-204, Jaxnikumar Naik | S37: 138400
B38: D-1204, Pravin Chaudhary & Geeta Chaudhary | C38: 50000 | F38: K/802,Vipul Kulshrestha | G38: 260717.7 | H38: 261600 | I38: 882.3 | K38: C-901,Placement & Consulting (Mohan Rohit) | L38: -620436 | O38: K/203, Priteshkumar P.Upadhyay, Paresh U | P38: 46000 | R38: K/203, Priteshkumar P.Upadhyay, Paresh U | S38: 215600
B39: D-1403,Jay Adthakkar | C39: 50000 | F39: B/1302 Karan Mehta | G39: 203587.7 | H39: 205000 | I39: 1412.3 | K39: D-1002, Kishorsinh Anopsinh Jadeja | L39: 611086 | O39: P-603, Rakesh Rathod | P39: 45500 | R39: P-603, Rakesh Rathod | S39: 215500
B40: D-301,Rajesh Vithaldas Chokshi | C40: 50000 | F40: F-203, Kalpesh Rohit Contractor & Nency Contractor | G40: 174417.7 | H40: 176200 | I40: 1782.3 | K40: D/101, Parth Madaan | L40: 565798 | O40: D-604, Kashyap Dave | P40: 36500 | R40: O-804,Rahulkumar Dharecha | S40: 170000
B41: D-304,Jinish Chimanbhai Patel | C41: 50000 | F41: C-1103, Sima Jigar Desai /Jigar S.Desai | G41: 0 | H41: 256000 | I41: 256000 | K41: D/102 Disha Bhagya Dave | L41: 38664 | O41: O-804,Rahulkumar Dharecha | P41: 36500 | R41: M/1004, Divya Tailor & Anurag Chhaparal | S41: 171300
B42: D-401, Bhartiben Mukeshbhai Halari / Dhaval Halari | C42: 50000 | F42: A-604., Deepakkumar, Ruchika Arora | G42: 0 | H42: 245000 | I42: 245000 | K42: D/1201 Shobhit Trapasiya | L42: 302539 | O42: M/1004, Divya Tailor & Anurag Chhaparal | P42: 37000 | R42: P-904, Niruben Soni, Mohit Soni | S42: 196000
B43: D-604, Kashyap Dave | C43: 50000 | F43: F-1003,Garima Rajawat & Jaisingh Sisodia | G43: 0 | H43: 240000 | I43: 240000 | K43: D-1204, Pravin Chaudhary & Geeta Chaudhary | L43: 34546 | O43: P-904, Niruben Soni, Mohit Soni | P43: 42000 | R43: P-503, Shekhar Mudaliar | S43: 180000
B44: D-902, Bhavna Vijay Jadav | C44: 50000 | F44: M/502 Javankiaben Koradiya, Naresh Koradiya | G44: 0 | H44: 171200 | I44: 171200 | K44: D-1303, Bharatkumar Khemnani | L44: 990100 | O44: P-503, Shekhar Mudaliar | P44: 38700 | R44: L-502, Shalabh Kaushik | S44: 219000
... B66: F-302,Jaimin Barot | C66: 50000 | F66: E-301, Vikramkumar | G66: 0 | H66: 208000 | I66: 208000 | K66: E-602, Dipak Singhal & Anchal Singhal | L66: 36840 | O66: (as per details) | P66: 48378 | R66: K-1202, Sagar Devajibhai Ladani | S66: 172000
B67: F-304, Ripal Vikash Jain (Ripal Bhatt) | C67: 50000 | F67: G-601, Hiren Darji | G67: 0 | H67: 197585 | I67: 197585 | K67: E-603,Yogita Amit Singhal | L67: 74256 | O67: A/702,Hemantkumar Ishvarlal Bhavsar | R67: K-702,Tapan Jayeshbhai Khimani | S67: 216000
B68: F-501,Maulikbhai Gondaliya | C68: 50000 | F68: K-402,Ravinjay Tiwari | G68: 0 | H68: 259600 | I68: 259600 | K68: E-701,Sanket Govinbhi Panchal | L68: 30527 | O68: CGST ON COLLECTION | R68: N-502, Sanjaykumar Mistry | S68: 138400
B69: F-503, Sanjay Bhadra | C69: 50000 | F69: K-1201, Riya Dasgupta | G69: 0 | H69: 219500 | I69: 219500 | K69: F-1002, Jigar J.Patel | L69: -265400 | O69: SGST ON COLLECTION | R69: M-801 Tarak B. Shah, Anjana Chauhan | S69: 160000
B70: F-703, Gaurav Sanjay Kankraj | C70: 50000 | F70: I-304, Mehulsinh Ranilsinh Rajput | G70: 263667.7 | H70: 265000 | I70: 1332.3 | K70: F-1003,Garima Rajawat & Jaisingh Sisodia | L70: 39880 | O70: A/701,Hemantkumar Ishwarlal Bhavsar | P70: 38116 | R70: K-104,Amogh Chitnis | S70: 172000
B71: F-801,Ashokkumar M.Sonagara | C71: 50000 | F71: A/702,Hemantkumar Ishvarlal Bhavsar | G71: 0 | H71: 212666 | I71: 212666 | K71: F-101, Jatin Prakash Gupta | L71: 211640 | O71: E-602, Dipak Singhal & Anchal Singhal | P71: 2200 | R71: I-301 Ankit Dharmendra Jani | S71: 195000
B72: F-802 ,Hemang Bharatbhai Ahya | C72: 50000 | F72: A/701,Hemantkumar Ishwarlal Bhavsar | G72: 0 | H72: 212666 | I72: 212666 | K72: F-104, Saurav Manibind | L72: 32828 | O72: B/503 Kishor M Bhatia | P72: 42500 | R72: M-203,Lokesh Bansilal Kalal | S72: 180550
B73: F-903,Krati Shrimali | C73: 50000 | F73: E-602, Dipak Singhal & Anchal Singhal | G73: 0 | H73: 185200 | I73: 185200 | K73: F-1101, Vijay Ojha | L73: 1354456 | O73: K-1202, Sagar Devajibhai Ladani | P73: 37000 | R73: N-202, Jaydevsinh Rana, Yuvraj Rana | S73: 182000
B74: F-904, Anuj Narayan Bhatt | C74: 50000 | F74: I-1104, Aashka Vivek Prajapati | G74: 0 | H74: 227000 | I74: 227000 | K74: F/1102,Meet Yogeshbhai Sheth | L74: 32828 | O74: K-702,Tapan Jayeshbhai Khimani | P74: 46000 | R74: O-703, Rahul M. Andharia | S74: 193000
B75: G/803 Jatin Maheshchandra Gujella | C75: 50000 | F75: B/503 Kishor M Bhatia | G75: 0 | H75: 240500 | I75: 240500 | K75: F-1201, Ashima Sehgal | L75: 26992 | O75: N-502, Sanjaykumar Mistry | P75: 30244 | R75: C-1303, Vikas Jain / Anamika Jain | S75: 189200
B76: G-1003, Parth Mathurbhai Dobariya | C76: 50000 | F76: K-1202, Sagar Devajibhai Ladani | G76: 0 | H76: 209000 | I76: 209000 | K76: F-1303, Shashank Chandraman Joshi | L76: 378614 | O76: M-801 Tarak B. Shah, Anjana Chauhan | P76: 34500 | R76: K-504,Udaykumar Vipinbhai Dave | S76: 220000
B77: G-1004, Sandeep Popat | C77: 50000 | F77: K-702,Tapan Jayeshbhai Khimani | G77: 0 | H77: 262000 | I77: 262000 | K77: F-202, Nandaben J. Parmar, Priyanka A. Chauhan | L77: 31290 | O77: K-104,Amogh Chitnis | P77: 37000 | R77: K-1204, Suman Mohanty | S77: 217300
B78: G-104, Daksha Rajeshbhai Darji | C78: 50000 | F78: N-502, Sanjaykumar Mistry | G78: 0 | H78: 168644 | I78: 168644 | K78: F-203, Kalpesh Rohit Contractor & Nency Contractor | L78: 35016 | O78: I-301 Ankit Dharmendra Jani | P78: 41700 | R78: D-1403,Jay Adthakkar | S78: 154100
...

Sheet SUN REALTY ATMOS-CALC
A1: Sun Realty Atmosphere
A4: GST PAYABLE ON COMMERCIAL CONSTRUCTION FOR THE MONTH OF AUG-26
A6: Supply | B6: AMOUNT | C6: RATE | D6: CGST | E6: SGST | F6: TOTAL
A8: SUN REALTY ATMOSPHERE RESIDENTIAL | B8: ='SUN REALTY ATMOS-MEMBERS COLL'!V66 | C8: 0.01 | D8: =+B8*C8/2 | E8: =+D8 | F8: =+D8+E8
A9: Less : Refund | B9: =+-'SUN REALTY ATMOS-MEMBERS COLL'!M66 | C9: 0.01 | D9: =+B9*C9/2 | E9: =+D9 | F9: =+D9+E9
A10: Less : Refund (GST PAID @1% INSTEAD OF 18%)
A11: Less: F-1101, Vijay Ojha [ Tax on the same has been already paid in mar'25, hence reversed] | C11: 0.01 | D11: =+B11*C11/2 | E11: =+D11 | F11: =+D11+E11
A12: AS PER RECO | C12: 0.01 | D12: =+B12*C12/2 | E12: =D12 | F12: =+D12+E12
C13: 0.01 | E13: =D13 | F13: =D13+E13
A15: TOTAL @ 1% | B15: =SUM(B8:B13) | D15: =SUM(D8:D13) | E15: =SUM(E8:E13) | F15: =SUM(F8:F13)
A17: Add:- PLC Amount Received | C17: 0.18 | D17: =B17*C17/2 | E17: =B17*C17/2 | F17: =+D17+E17
B18: 0 | C18: 0.18 | D18: =B18*C18/2 | E18: =B18*C18/2 | F18: =+D18+E18
C19: 0.18 | D19: =B19*C19/2 | E19: =B19*C19/2 | F19: =+D19+E19
A20: TOTAL @ 18% | B20: =SUM(B17:B19) | D20: =SUM(D17:D19) | E20: =SUM(E17:E19) | F20: =SUM(F17:F19)
A22: SUN REALTY ATMOSPHERE RESIDENTIAL ( Sale Deed More Than 45 Lakhs ) | B22: =+'SUN REALTY ATMOS-MEMBERS COLL'!V78 | C22: 0.05 | D22: =+B22*C22/2 | E22: =+D22 | F22: =+D22+E22
A23: Less : Refund @5% | B23: =-'SUN REALTY ATMOS-MEMBERS COLL'!I78 | C23: 0.05 | D23: =B23*C23/2 | E23: =B23*C23/2 | F23: =+D23+E23
A24: TOTAL @ 5% | B24: =SUM(B22:B23) | D24: =SUM(D22:D23) | E24: =SUM(E22:E23) | F24: =SUM(F22:F23)
A26: SUN REALTY ATMOSPHERE COMMERCIAL | B26: ='SUN REALTY ATMOS-MEMBERS COLL'!V104+B82 | C26: 0.05 | D26: =B26*C26/2 | E26: =+D26 | F26: =+D26+E26
A27: Less : Refund | B27: =-'SUN REALTY ATMOS-MEMBERS COLL'!M104-'SUN REALTY ATMOS-MEMBERS COLL'!I104 | C27: 0.05 | D27: =B27*C27/2 | E27: =B27*C27/2 | F27: =+D27+E27
C28: 0.05
C29: 0.05 | D29: =B29*C29/2 | E29: =B29*C29/2 | F29: =+D29+E29
A30: TOTAL @ 5% | B30: =SUM(B26:B29) | D30: =SUM(D26:D29) | E30: =SUM(E26:E29) | F30: =SUM(F26:F29)
A32: TOTAL | B32: =+B15+B20+B24+B30 | D32: =+D15+D20+D24+D30 | E32: =+E15+E20+E24+E30 | F32: =+F15+F20+F24+F30
A34: After BU sale deed Exempt sale | B34: 0
A37: Supply | B37: AMOUNT | C37: RATE | D37: CGST | E37: SGST | F37: TOTAL
A38: TAXABLE VALUE @18% | C38: 0.18 | D38: =B38*C38/2 | E38: =+D38 | F38: =+D38+E38
A39: TAXABLE VALUE @5% | C39: 0.05 | D39: =B39*C39/2 | E39: =+D39 | F39: =+D39+E39
A40: TAXABLE VALUE @1% | C40: 0.01 | D40: =B40*C40/2 | E40: =+D40 | F40: =+D40+E40
A41: TOTAL | B41: =SUM(B38:B40) | D41: =SUM(D38:D40) | E41: =SUM(E38:E40) | F41: =+D41+E41 | H41: =8608-3304
A43: GST PAYABLE UNDER RCM FOR THE MONTH OF AUG-26
A45: Service | B45: AMOUNT | C45: RATE | D45: CGST | E45: SGST | F45: TOTAL
A47: SUN REALTY ATMOSPHERE
A48: Advocate fees | C48: 0.18 | D48: =+B48*9/100 | E48: =+D48 | F48: =+D48+E48
A49: Carting and Transportation (Gayatri Sales Corp & Ashokji Vanzara, mahesh v zamada) | B49: 0 | C49: 0.05 | D49: =+B49*0.025 | E49: =+D49 | F49: =+D49+E49
A50: Security Services | B50: 0 | C50: 0.18 | D50: =+B50*9% | E50: =+B50*9% | F50: =SUM(D50:E50)
A51: Royalty Expenses | B51: 0 | C51: 0.18 | D51: =+B51*9% | E51: =+B51*9% | F51: =SUM(D51:E51)
A53: TOTAL | B53: =SUM(B47:B52) | D53: =SUM(D47:D52) | E53: =SUM(E47:E52) | F53: =SUM(F47:F52)
A55: INELIGIBLE CREDIT FOR THE MONTH OF AUG-26
A57: PARTICULARS | B57: CGST | C57: SGST | D57: IGST
A59: ITC FOR THE AUG-26 | B59: 0 | C59: =B59 | D59: 0
...

Sheet SUN REALTY FOOTPRINT- MEMBERS
A1: Sun Realty
A4: CALCULATION For the month of AUG-26
A6: MEMBERS COLLECTION
A7: Flat No. | B7: Name of Owner | C7: CR SIDE | D7: Receipt of Registration Fees/JV / REFUNDABLE(Cr) | E7: Payment of Reg Fees on Behalf of Client / JV REFUNDABLE (Dr) | F7: Receipt of Stamp Duty/JV (Cr) | G7: Payment of Stamp Duty/JV (Dr) | H7: cheque withdrawn | I7: REFUND OF SAME PEROID WITH GST | J7: REFUND WITHOUT GST | L7: AEC,AUDA JV | M7: NET RECEIPT | N7: cgst
K8: Payment for Cancellation of unit /Reg fee/Stamp Duty
A9: A/0104 | B9: A-104,Gautam Prakash Narayan , Ragini Gautam | C9: 864614.7 | E9: =+D9 | F9: 255702.7 | G9: =+F9 | M9: =C9-D9-F9-H9 | N9: =M9*0.5/100
A10: A/0301 | B10: A-301, Savitaben Mohanbhai Maheriya | C10: 455446 | E10: =+D10 | G10: =F10 | H10: 0 | M10: =C10-D10-F10-H10 | N10: =M10*0.5/100
A11: A/0401 | B11: A/401, Nishaben Pragnesh Modi | C11: 179286.7 | E11: =+D11 | F11: 179286.7 | G11: =F11 | M11: =C11-D11-F11-H11 | N11: =M11*0.5/100
A12: A/0501 | B12: A/501, Ashviniben Rameshbhai Kanzariya | C12: 171735.7 | E12: =+D12 | F12: 171735.7 | G12: =F12 | M12: =C12-D12-F12-H12 | N12: =M12*0.5/100
A13: A/0602 | B13: A-602, Pratik Dipak Shah | C13: 42884.75 | E13: =+D13 | F13: 42885 | G13: =F13 | M13: =C13-D13-F13-H13 | N13: =M13*0.5/100
A14: A/0603 | B14: A-603, Mohitkumar J.Agravat / Anjali M.Agravat | C14: 489952 | E14: =+D14 | G14: =F14 | M14: =C14-D14-F14-H14 | N14: =M14*0.5/100
A15: A/0902 | B15: A-902, Yogina Tripathi /Sanjay Tripathi | C15: 1980198 | E15: =+D15 | G15: =F15 | M15: =C15-D15-F15-H15 | N15: =M15*0.5/100
A16: A/1001 | B16: A/1001 Reena Dadlani | C16: 264096 | E16: =+D16 | F16: =239096+25000 | G16: 239096 | M16: =C16-D16-F16-H16 | N16: =M16*0.5/100
A17: A/1304 | B17: A1304, Mohit Raja | C17: 792080 | E17: =+D17 | G17: =F17 | M17: =C17-D17-F17-H17 | N17: =M17*0.5/100
A18: B/0203 | B18: B-203, Shubham Alkeshbhai Gohel | C18: 434908 | E18: =+D18 | G18: =F18 | M18: =C18-D18-F18-H18 | N18: =M18*0.5/100
A19: B/0504 | B19: B/504, Prakashnath Devnath Jogi | C19: 311477 | D19: =25000+43715 | E19: =+D19 | F19: 201955 | G19: =+F19 | M19: =C19-D19-F19-H19 | N19: =M19*0.5/100
A20: B/0601 | B20: B-601, Umeshkumar Hargovanbhai Kadiya | C20: 1010615.7 | E20: =+D20 | F20: 264963.7 | G20: =F20 | M20: =C20-D20-F20-H20 | N20: =M20*0.5/100
A21: C/0101 | B21: C-101, Sangita Pankaj Sharma | C21: 242535 | D21: =2500+25000 | E21: =+D21 | F21: =184310 | G21: =F21 | M21: =C21-D21-F21-H21 | N21: =M21*0.5/100
A22: C/0401 | B22: C-401,Manoj Dayaram Khanchandani | C22: 638164 | E22: =+D22 | G22: =F22 | M22: =C22-D22-F22-H22 | N22: =M22*0.5/100
A23: C/0402 | B23: C402,Mukeshkumar, Mamta | C23: 236257.7 | D23: 40968.85 | E23: =+D23 | F23: 195288.85 | G23: =F23 | M23: =C23-D23-F23-H23 | N23: =M23*0.5/100
A24: C/0403 | B24: C-403,Ravi D.Labana & Dashrathbhai P. Labana | C24: 20792 | E24: =+D24 | G24: =F24 | M24: =C24-D24-F24-H24 | N24: =M24*0.5/100
A25: C/0601 | B25: C-601,Hiral DInesh Madhu /Manan K.Shah | C25: 475248 | E25: =+D25 | G25: =F25 | M25: =C25-D25-F25-H25 | N25: =M25*0.5/100
A26: C/0604 | B26: C-604, Ganesh Mahto | C26: 218940.7 | D26: 218940.7 | E26: =+D26 | G26: =F26 | M26: =C26-D26-F26-H26 | N26: =M26*0.5/100
A27: C/0704 | B27: C704, Dhanjani Honey / Hemani Mayur Nileshbhai | C27: 588388 | E27: =+D27 | G27: =F27 | M27: =C27-D27-F27-H27 | N27: =M27*0.5/100
A28: C/0803 | B28: C-803, Bhargav Amrishbhai Ubhadiya | C28: 495050 | E28: =+D28 | G28: =F28 | M28: =C28-D28-F28-H28 | N28: =M28*0.5/100
A29: C/0804 | B29: C-804, Shilpi Neeraj Sharma, Neeraj Shamra | C29: 27094.75 | D29: 27094.75 | E29: =+D29 | G29: =F29 | M29: =C29-D29-F29-H29 | N29: =M29*0.5/100
A30: C/0901 | B30: C/901, Rajeshkumar Pandya | C30: 490243 | D30: =25000+42352 | E30: =+D30 | F30: 195277 | G30: =F30 | I30: 113807 | M30: =C30-D30-F30-H30 | N30: =M30*0.5/100
A31: C/1003 | B31: C-1003,Kanika J.Mahadevwala | C31: 35174.75 | D31: 35174.75 | E31: =+D31 | G31: =F31 | M31: =C31-D31-F31-H31 | N31: =M31*0.5/100
A32: C/1101 | B32: C-1101, Harikrishna Madhu | C32: 222092.7 | D32: 222092.7 | E32: =+D32 | G32: =F32 | M32: =C32-D32-F32-H32 | N32: =M32*0.5/100
A33: C/1302 | B33: C-1302, Ishita Purohit | C33: 579208 | E33: =+D33 | G33: =F33 | M33: =C33-D33-F33-H33 | N33: =M33*0.5/100
A34: C/1403 | B34: C-1403, Rekhaben Hiteshkumar Agrawal | C34: 184377.7 | D34: 184377.7 | E34: =+D34 | G34: =F34 | M34: =C34-D34-F34-H34 | N34: =M34*0.5/100
A35: D/0301 | B35: D-301, Arunkumar Kamat & Puja Kumari | C35: 241183.7 | D35: 241183.7 | E35: =+D35 | G35: =F35 | M35: =C35-D35-F35-H35 | N35: =M35*0.5/100
A36: D/0302 | B36: D-302,Ashokkumar Kamat | C36: 235141.7 | D36: 40778.85 | E36: =+D36 | F36: 194362.85 | G36: =F36 | M36: =C36-D36-F36-H36 | N36: =M36*0.5/100
A37: D/0303 | B37: D-303, Sanjaykumar R. Patel & Sunitaben S.Patel | C37: 2189128.7 | D37: =169955.7+31116 | E37: =+D37 | F37: 140216 | G37: =F37 | I37: 613901 | M37: =C37-D37-F37-H37 | N37: =M37*0.5/100
A38: D/0304 | B38: D-304, Anju Barua | C38: 1014.75 | D38: 1014.75 | E38: =+D38 | G38: =F38 | M38: =C38-D38-F38-H38 | N38: =M38*0.5/100
A39: D/0402 | B39: D-402, Dharmendra Kumar | C39: 204465.7 | D39: 35578.85 | E39: =+D39 | F39: 168886.85 | G39: =F39 | M39: =C39-D39-F39-H39 | N39: =M39*0.5/100
A40: D/0501 | B40: D/501-West Wing Infra.P.L. Kalpeshbhai | C40: 202543.7 | D40: 202543.7 | E40: =+D40 | G40: =F40 | M40: =C40-D40-F40-H40 | N40: =M40*0.5/100
A41: D/0601 | B41: D-601,-West Wing Infra. P.L. Neetaben Prajapati | C41: 204077.7 | D41: 204077.7 | E41: =+D41 | G41: =F41 | M41: =C41-D41-F41-H41 | N41: =M41*0.5/100
A42: D-0602 | B42: D-602, Meena Bohra | C42: 205370 | D42: =2500+25000 | E42: =+D42 | F42: 177870 | G42: =F42 | M42: =C42-D42-F42-H42 | N42: =M42*0.5/100
A43: D/0703 | B43: D-703, Harsh P. Bhatt & Vrushti H. Bhatt | E43: =+D43 | G43: =F43 | M43: =C43-D43-F43-H43 | N43: =M43*0.5/100
...

Sheet FOOTPRINT- CALCULATION
A1: Sun Realty Footprint
A2: GST PAYABLE ON COMMERCIAL CONSTRUCTION FOR THE MONTH OF AUG'26
A4: Supply | B4: AMOUNT | C4: RATE | D4: CGST | E4: SGST | F4: TOTAL
A6: SUN REALTY Footprint RESIDENTIAL | B6: ='SUN REALTY FOOTPRINT- MEMBERS'!M218 | C6: 0.01 | D6: =B6*0.5% | E6: =B6*0.5/100 | F6: =+D6+E6
A7: Less : Refund | B7: =-'SUN REALTY FOOTPRINT- MEMBERS'!I218 | C7: 0.01 | D7: =B7*0.5% | E7: =D7 | F7: =+D7+E7
A8: Less: Entry RECTIFIED IN BOOKS OF APRIL-26 F-401, Shubham S/o Gajendra Kumar Mishra | B8: -2800 | C8: 0.01 | D8: =B8*0.5% | E8: =D8 | F8: =+D8+E8 | H8: =38921
A9: LESS : REFUND/PAYMENT ENTRY DELETED FROM BOOKS OF APR-26 D-503,Hansaben Kanakray Rathod_cancelled | B9: 420792 | C9: 0.01 | D9: =B9*0.5% | E9: =D9 | F9: =+D9+E9 | H9: 36121
H10: =+H8-H9
A11: SUN REALTY Footprint COMMERCIAL | B11: =+'SUN REALTY FOOTPRINT- MEMBERS'!M230 | C11: 0.05 | D11: =B11*C11/2 | E11: =B11*C11/2 | F11: =+D11+E11
A12: Less : Refund | B12: =-'SUN REALTY FOOTPRINT- MEMBERS'!I230 | C12: 0.05 | D12: =B12*C12/2 | E12: =B12*C12/2 | F12: =+D12+E12
A14: TOTAL | B14: =SUM(B6:B13) | D14: =SUM(D6:D13) | E14: =SUM(E6:E13) | F14: =SUM(F6:F13)
A15: B2C
A16: Cancellation Charges Income | C16: 0.18 | D16: =B16*C16/2 | E16: =B16*C16/2 | F16: =+D16+E16
A17: After BU sale deed Exempt sale | B17: 84631993 | C17: 0
A18: TOTAL | B18: =+B16+B15+B17 | D18: =+D16+D15+D17 | E18: =+E16+E15+E17 | F18: =+F16+F15+F17
A19: NET TOTAL | B19: =+B14+B18 | D19: =+D14+D18 | E19: =+E14+E18 | F19: =+F14+F18
A21: GST PAYABLE UNDER RCM FOR THE MONTH OF AUG-26
A22: .
A23: Service | B23: AMOUNT | C23: RATE | D23: CGST | E23: SGST | F23: TOTAL
A25: SUN REALTY Footprint
A26: Advocate fees | B26: 0 | C26: 0.18 | D26: =+B26*9/100 | E26: =+D26 | F26: =+D26+E26
A27: Carting and Transportation (Gayatri Sales Corp) | C27: 0.05 | D27: =+B27*0.025 | E27: =+D27 | F27: =+D27+E27
A28: Security Services | C28: 0.18 | D28: =+B28*9% | E28: =+B28*9% | F28: =SUM(D28:E28)
A29: Sponsor Ship Exp | C29: 0.18 | D29: =+B29*9% | E29: =+B29*9% | F29: =SUM(D29:E29)
A31: TOTAL | B31: =SUM(B25:B30) | D31: =SUM(D25:D30) | E31: =SUM(E25:E30) | F31: =SUM(F25:F30)
A33: INELIGIBLE CREDIT FOR THE MONTH OF AUG -26
A35: PARTICULARS | B35: CGST | C35: SGST | D35: IGST
A37: ITC FOR THE AUG-26 | B37: =739575.92 | C37: =+B37
A38: Add: Ineligible ITC | C38: =+B38
A39: Add: Ineligible ITC FOR RCM | B39: =+D31 | C39: =+E31
A40: Total ineligible CENVAYT | B40: =SUM(B37:B39) | C40: =SUM(C37:C39) | D40: =SUM(D37:D39)
A41: TOTAL | B41: =SUM(B40:B40) | C41: =SUM(C40:C40) | D41: =SUM(D40:D40)
A44: GST Payable for the month of AUG'26
A46: PARTICULARS | B46: CGST | C46: SGST | D46: TOTAL
A48: =+A6 | B48: =+D19 | C48: =+E19 | D48: =+F19
A50: TOTAL PAYABLE FOR RESIDENTIAL INCLUDING IGST | B50: =+B48+B49 | C50: =+C48+C49 | D50: =+D48+D49
A52: GST UNDER RCM
A53: SUN Footprint | B53: =D27+D28+D26+D29 | C53: =B53 | D53: =+B53+C53
A54: SUN OFFICE | D54: =+B54+C54
A55: GST Payable | B55: =+B50+B53+B54 | C55: =+C50+C53+C54 | D55: =+D50+D53+D54
...

Sheet SUN PARK WEST- MEMBER COLL.
A1: Sun Realty
A4: CALCULATION For the month of AUG-26
A6: MEMBERS COLLECTION
A7: Flat No. | B7: Name of Owner | C7: CR SIDE | D7: Receipt of Registration Fees/JV (Cr) | E7: Payment of Reg Fees on Behalf of Client / JV (Dr) | F7: Receipt of Stamp Duty/JV (Cr) | G7: Payment of Stamp Duty/JV (Dr) | H7: REFUND OF SAME PEROID WITH GST | I7: CHEQUE RETURN | J7: REFUND WITHOUT GST | K7: NET RECEIPT | L7: GST
A9: A/0201 | B9: A-201,Pareshkumar B.Prajapati | C9: 427256.75 | D9: 1514.75 | E9: =+D9 | K9: =C9-D9-F9-I9 | L9: =+K9*1%/2
A10: A/0301 | B10: A-301, Mrs.Ramla Sahu | C10: 396040 | K10: =C10-D10-F10 | L10: =+K10*1%/2
A11: A/0302_x000D_ | B11: A-302, Vishal Vaidhya & Bhakti Vaidhya | C11: 148515 | K11: =C11-D11-F11 | L11: =+K11*1%/2
A12: A/0401_x000D_ | B12: A-401, Dimpalkumar Jayendraprasad Dave | C12: 257426 | K12: =C12-D12-F12 | L12: =+K12*1%/2
A13: A/0501 | B13: A-501, Alpaben Raj | C13: 1981714.8 | D13: 1514.75 | E13: =+D13 | K13: =C13-D13-F13 | L13: =+K13*1%/2
A14: A/0503 | B14: A/503, Shilpa Indoria | C14: 272278 | E14: =+D14 | K14: =C14-D14-F14 | L14: =+K14*1%/2
A15: A/0702 | B15: A-702, Rajvi Pankit Shah | C15: 356436 | E15: =+D15 | K15: =C15-D15-F15 | L15: =+K15*1%/2
A16: A/0903_x000D_ | B16: A/ 903, Hardik Meravan | C16: 293070 | E16: =+D16 | K16: =C16-D16-F16 | L16: =+K16*1%/2
A17: A/1003_x000D_ | B17: A-1003, Vishal Dobriya | C17: 556436 | E17: =+D17 | K17: =C17-D17-F17 | L17: =+K17*1%/2
A18: A/1004 | B18: A-1004, Urmila Navin Gala | C18: 538614 | K18: =C18-D18-F18 | L18: =+K18*1%/2
A19: A/1103_x000D_ | B19: A-1103, Jeet Gandhi | C19: 297030 | E19: =+D19 | K19: =C19-D19-F19 | L19: =+K19*1%/2
A20: A/1203_x000D_ | B20: A/1203 Ashok G. Kagathara | C20: 331683 | K20: =C20-D20-F20 | L20: =+K20*1%/2
A21: A/1303 | B21: A-1303, Ankur Gordhanbhai Patel | C21: 331684 | K21: =C21-D21-F21 | L21: =+K21*1%/2
A22: B/0101_x000D_ | B22: B/101, Dhairya Samirbhai Pandya | C22: 371288 | K22: =C22-D22-F22 | L22: =+K22*1%/2
A23: B/0602_x000D_ | B23: B-602,Vimala Kushwaha | C23: 396040 | I23: 198020 | K23: =C23-D23-F23 | L23: =+K23*1%/2
A24: B/0902 | B24: B/902 Himanshu Gupta / Nidhi Gupta | C24: 278712 | K24: =C24-D24-F24 | L24: =+K24*1%/2
A25: B/1001_x000D_ | B25: B-1001,Thakor Rohitji | C25: 1485149 | I25: 990100 | K25: =C25-D25-F25 | L25: =+K25*1%/2
A26: B/1101_x000D_ | B26: B-1101. Savitriben Thakor | C26: 1942574 | K26: =C26-D26-F26 | L26: =+K26*1%/2
A27: C/0501 | B27: C-501, Audesh Mansaram Vishvakarma | C27: 297030 | K27: =C27-D27-F27-I27 | L27: =+K27*1%/2
A28: D/0201 | B28: D-201, Riddhi Bhavya Kothari | C28: 940594 | K28: =C28-D28-F28-I28 | L28: =+K28*1%/2
A29: D/0202 | B29: D/202 Palak Atulkumar Turakhia | C29: 466000 | K29: =C29-D29-F29 | L29: =+K29*1%/2
A30: D/0302 | B30: D/302 Nirav Ramjibhai Mehta | C30: 212872 | K30: =C30-D30-F30 | L30: =+K30*1%/2
A31: D/0502_x000D_ | B31: D/502, Varshaben,Nikunj, Rajeshbhai S. Modi | C31: 247524 | K31: =C31-D31-F31 | L31: =+K31*1%/2
A32: D/0601_x000D_ | B32: D/601 Mayank Ramani | C32: 435644 | K32: =C32-D32-F32 | L32: =+K32*1%/2
A33: D/0701_x000D_ | B33: D-701, Rameshchanra Somji Barot | C33: 489627 | K33: =C33-D33-F33 | L33: =+K33*1%/2
A34: D/0704_x000D_ | B34: D/704 Janya Meghrajani, Anshu Meghrajani | C34: 227722 | K34: =C34-D34-F34 | L34: =+K34*1%/2
A35: D/0803_x000D_ | B35: D-803, Aradhana D. & Dhaval Pandit | C35: 247525 | K35: =C35-D35-F35 | L35: =+K35*1%/2
A36: D/0804 | B36: D-804, Krunal Shah | C36: 401683 | K36: =C36-D36-F36 | L36: =+K36*1%/2
A37: D/0901_x000D_ | B37: D-901,Anandkumar Prakashbhai Vaishnani | C37: 202970 | E37: =+D37 | G37: =F37 | K37: =C37-D37-F37 | L37: =+K37*1%/2
A38: D/0903_x000D_ | B38: D-903, Ravi Virani | C38: 1023763 | G38: =F38 | K38: =C38-D38-F38 | L38: =+K38*1%/2
A39: D/1002_x000D_ | B39: D-1002, Mrugesh Pankajkumar Sheth | C39: 410892 | G39: =F39 | K39: =C39-D39-F39 | L39: =+K39*1%/2
A40: D/1003 | B40: D-1003, Suresh C Jagani & Sonalben S. Jagnani | C40: 99010 | K40: =C40-D40-F40-I40 | L40: =+K40*1%/2
A41: D/1102 | B41: D-1102, Urmi Shail Shah | C41: 128712 | K41: =C41-D41-F41 | L41: =+K41*1%/2
A42: D/1103 | B42: D-1103, Smitkumar R. Vachhani | C42: 223267 | K42: =C42-D42-F42 | L42: =+K42*1%/2
A43: D/1202 | B43: D-1202, Kiritbhai Muljibhai Bhut | C43: 235644 | G43: =F43 | K43: =C43-D43-F43 | L43: =+K43*1%/2
A44: D/1303_x000D_ | B44: D/1303, Hiteshkumar S. Shah & Avaniben H.Shah | C44: 269306 | K44: =C44-D44-F44 | L44: =+K44*1%/2
...

Sheet SUN PARK WEST
A1: Sun Realty -SUN PARK WEST
A2: GST PAYABLE ON COMMERCIAL CONSTRUCTION FOR THE MONTH OF AUG'26
A4: Supply | B4: AMOUNT | C4: RATE | D4: CGST | E4: SGST | F4: TOTAL
H5: FILED GSTR-1 | I5: TAXABLE VALUE | J5: CGST | K5: SGST
A6: SUN REALTY -SUN PARK WEST RESIDENTIAL | B6: =+'SUN PARK WEST- MEMBER COLL.'!K74 | C6: 0.01 | D6: =B6*0.5% | E6: =B6*0.5/100 | F6: =+D6+E6 | H6: 46113 | I6: 198020
A7: SUSPNESE A/C PAID @1% [ Deleted From Books of Apr-26] | B7: =+-I11 | C7: 0.01 | D7: =B7*0.5% | E7: =B7*0.5/100 | F7: =+D7+E7
A8: Less : Refund/Chq Return | B8: =-'SUN PARK WEST- MEMBER COLL.'!H74-'SUN PARK WEST- MEMBER COLL.'!I74 | C8: 0.01 | D8: =B8*0.5% | E8: =D8 | F8: =+D8+E8
A10: SUN REALTY -SUN PARK WEST RESIDENTIAL | B10: =+'SUN PARK WEST- MEMBER COLL.'!K85 | C10: 0.05 | D10: =B10*C10/2 | E10: =B10*C10/2 | F10: =+D10+E10
A11: SUSPENSE TRANSFER TO MEMBERS A/C@5% [ AS PER GST RECO] | B11: =+I19-I26 | C11: 0.05 | D11: =B11*C11/2 | E11: =B11*C11/2 | F11: =+D11+E11 | I11: =SUM(I6:I10) | J11: =SUM(J6:J10) | K11: =SUM(K6:K10)
A12: Less : Refund/Chq Return | B12: =-'SUN PARK WEST- MEMBER COLL.'!H85 | C12: 0.05 | D12: =B12*C12/2 | E12: =B12*C12/2 | F12: =+D12+E12
H13: AS PER BOOKS | I13: TAXABLE VALUE | J13: CGST | K13: SGST
A14: SUN REALTY -SUN PARK WEST COMMERCIAL | B14: =+'SUN PARK WEST- MEMBER COLL.'!K97 | C14: 0.05 | D14: =B14*C14/2 | E14: =B14*C14/2 | F14: =+D14+E14
A15: Less : Refund/Chq Return | B15: =-'SUN PARK WEST- MEMBER COLL.'!H97 | C15: 0.05 | D15: =B15*C15/2 | E15: =B15*C15/2 | F15: =+D15+E15
A17: TOTAL | B17: =SUM(B6:B15) | D17: =SUM(D6:D15) | E17: =SUM(E6:E15) | F17: =SUM(F6:F15)
A19: GST PAYABLE UNDER RCM FOR THE MONTH OF AUG'26 | I19: =SUM(I14:I18) | J19: =SUM(J14:J18) | K19: =SUM(K14:K18)
A20: .
A21: Service | B21: AMOUNT | C21: RATE | D21: CGST | E21: SGST | F21: TOTAL | H21: TAXABLE VALUE CHANGE IN BOOKS AFTER FILING GSTR-1 OF AUG-25
H22: FILED GSTR-1 | I22: TAXABLE VALUE | J22: CGST | K22: SGST
A23: SUN REALTY-SUN PARK WEST
A24: Advocate fees | B24: 0 | C24: 0.18 | D24: =+B24*9/100 | E24: =+D24 | F24: =+D24+E24 | H24: AS PER BOOKS
A25: Carting and Transportation (Gayatri Sales Corp)/ ASHOK P VANJARA | B25: 0 | C25: 0.05 | D25: =+B25*0.025 | E25: =+D25 | F25: =+D25+E25
A26: Security Services | B26: 18000 | C26: 0.18 | D26: =+B26*9% | E26: =+B26*9% | F26: =SUM(D26:E26) | H26: EXCESS GST PAID | I26: =I23-I25 | J26: =J23-J25 | K26: =K23-K25
A27: Sponsorship Exp | C27: 0.18 | D27: =+B27*9% | E27: =+B27*9% | F27: =SUM(D27:E27)
A28: Royalty Exp. | C28: 0.18 | D28: =+B28*9% | E28: =+B28*9% | F28: =SUM(D28:E28)
A29: TOTAL | B29: =SUM(B23:B28) | D29: =SUM(D23:D28) | E29: =SUM(E23:E28) | F29: =SUM(F23:F28)
A31: INELIGIBLE CREDIT FOR THE MONTH OF AUG'26
A33: PARTICULARS | B33: CGST | C33: SGST | D33: IGST
A35: ITC FOR THE AUG-26 | C35: =+B35 | D35: 0
A36: Direct Exp. | B36: =353435.84 | C36: =+B36
A37: Indirect Exp. | B37: 540 | C37: =+B37 | D37: 0
A38: Add: Ineligible ITC | C38: =+B38
A39: Add: Ineligible ITC FOR RCM | B39: =+D29 | C39: =+E29
A40: Total ineligible CENVAYT | B40: =SUM(B35:B39) | C40: =SUM(C35:C39) | D40: =SUM(D35:D39)
A41: TOTAL | B41: =SUM(B40:B40) | C41: =SUM(C40:C40) | D41: =SUM(D40:D40)
A44: GST Payable for the month of AUG'26
A46: PARTICULARS | B46: CGST | C46: SGST | D46: TOTAL
A48: =+A6 | B48: =+D17 | C48: =+E17 | D48: =+F17
A50: TOTAL PAYABLE FOR RESIDENTIAL INCLUDING IGST | B50: =+B48+B49 | C50: =+C48+C49 | D50: =+D48+D49
A52: GST UNDER RCM
A53: SUN Footprint | B53: =+D29 | C53: =B53 | D53: =+B53+C53
...

Sheet SUN SILVER SPRING-MEMBER COLL
A1: Sun Realty -SUN SILVER SPRING
A4: CALCULATION For the month of APR-25 TO DEC-25
A5: FLATE MEMBERS COLLECTION @ 5%
A6: Flat No. | B6: Name of Owner | C6: CR SIDE | D6: Receipt of Registration Fees | E6: Payment of Reg Fees on Behalf of Client | F6: Receipt of Stamp Duty/JV (Cr) | G6: Payment of Stamp Duty/JV (Cr) | H6: REFUND OF SAME PEROID | J6: REFUND WITHOUT GST | K6: NET RECEIPT
L7: GST
K8: =C8-D8-F8 | L8: =K8*2.5/100
K9: =C9-D9-F9 | L9: =K9*2.5/100
K10: =C10-D10-F10 | L10: =K10*2.5/100
K11: =C11-D11-F11 | L11: =K11*2.5/100
K12: =C12-D12-F12 | L12: =K12*2.5/100
K13: =C13-D13-F13 | L13: =K13*2.5/100
K14: =C14-D14-F14 | L14: =K14*2.5/100
K15: =C15-D15-F15 | L15: =K15*2.5/100
K16: =C16-D16-F16 | L16: =K16*2.5/100
K17: =C17-D17-F17 | L17: =K17*2.5/100
K18: =C18-D18-F18 | L18: =K18*2.5/100
K19: =C19-D19-F19 | L19: =K19*2.5/100
K20: =C20-D20 | L20: =K20*2.5/100
A21: Total | C21: =SUM(C8:C20) | D21: =SUM(D8:D20) | E21: =SUM(E8:E20) | F21: =SUM(F8:F20) | G21: =SUM(G8:G20) | H21: =SUM(H8:H20) | J21: =SUM(J8:J20) | K21: =SUM(K8:K20)

Sheet SUN SILVER SPRING
A1: Sun Realty -SUN SILVER SPRING
A2: GST PAYABLE ON COMMERCIAL CONSTRUCTION FOR THE MONTH OF AUG-26
A4: Supply | B4: AMOUNT | C4: RATE | D4: CGST | E4: SGST | F4: TOTAL
A7: SUN REALTY -SUN SILVER SPRING RESIDENTIAL | B7: =+'SUN SILVER SPRING-MEMBER COLL'!K21 | C7: 0.05 | D7: =B7*C7/2 | E7: =B7*C7/2 | F7: =+D7+E7
B8: 0 | C8: 0.05 | D8: =B8*C8/2 | E8: =B8*C8/2 | F8: =+D8+E8
A9: Less : Refund | B9: =-'SUN SILVER SPRING-MEMBER COLL'!H21 | C9: 0.05 | D9: =B9*C9/2 | E9: =B9*C9/2 | F9: =+D9+E9
A11: SUN REALTY -SUN PARK WEST COMMERCIAL | C11: 0.05 | D11: =B11*C11/2 | E11: =B11*C11/2 | F11: =+D11+E11
A12: Less : Refund | C12: 0.05 | D12: =B12*C12/2 | E12: =B12*C12/2 | F12: =+D12+E12
A14: TOTAL | B14: =SUM(B6:B12) | D14: =SUM(D6:D12) | E14: =SUM(E6:E12) | F14: =SUM(F6:F12)
A16: GST PAYABLE UNDER RCM FOR THE MONTH OF AUG-26
A17: .
A18: Service | B18: AMOUNT | C18: RATE | D18: CGST | E18: SGST | F18: TOTAL
A20: SUN REALTY-SUN SILVER SPRING
A21: Advocate fees | B21: 0 | C21: 0.18 | D21: =+B21*9/100 | E21: =+D21 | F21: =+D21+E21
A22: Carting and Transportation (Gayatri Sales Corp)/ SHAKTI TRANSPORT | C22: 0.05 | D22: =+B22*0.025 | E22: =+D22 | F22: =+D22+E22
A23: Security Services (AUG-25 TO AUG-26) | C23: 0.18 | D23: =+B23*9% | E23: =+B23*9% | F23: =SUM(D23:E23)
A24: Sponsorship Exp | C24: 0.18 | D24: =+B24*9% | E24: =+B24*9% | F24: =SUM(D24:E24)
A25: Royalty Exp. | C25: 0.18 | D25: =+B25*9% | E25: =+B25*9% | F25: =SUM(D25:E25)
A26: TOTAL | B26: =SUM(B20:B25) | D26: =SUM(D20:D25) | E26: =SUM(E20:E25) | F26: =SUM(F20:F25)
A28: INELIGIBLE CREDIT FOR THE MONTH OF AUG-26
A30: PARTICULARS | B30: CGST | C30: SGST | D30: IGST
A32: ITC FOR THE AUG-26
A33: Direct Exp. | B33: 30599.11 | C33: =+B33 | D33: 0
A34: Indirect Exp. | B34: 0 | C34: =+B34 | D34: 0
A35: Add: Ineligible ITC | C35: =+B35
A36: Add: Ineligible ITC FOR RCM | B36: =+D26 | C36: =+E26
A37: Total ineligible CENVAYT | B37: =SUM(B32:B36) | C37: =SUM(C32:C36) | D37: =SUM(D32:D36)
A38: TOTAL | B38: =SUM(B37:B37) | C38: =SUM(C37:C37) | D38: =SUM(D37:D37)
A41: GST Payable for the month of AUG-26
A43: PARTICULARS | B43: CGST | C43: SGST | D43: TOTAL
A45: =+A7 | B45: =+D14 | C45: =+E14 | D45: =+F14
A47: TOTAL PAYABLE FOR RESIDENTIAL INCLUDING IGST | B47: =+B45+B46 | C47: =+C45+C46 | D47: =+D45+D46
A49: GST UNDER RCM
A50: SUN SILVER SPRING | B50: =+D26 | C50: =B50 | D50: =+B50+C50
A51: SUN OFFICE | D51: =+B51+C51
A52: GST Payable | B52: =+B47+B50+B51 | C52: =+C47+C50+C51 | D52: =+D47+D50+D51
A53: Net GST Payable | B53: =+B52 | C53: =+C52 | D53: =+D52
A56: As per Note | C56: Taxable Amount | D56: CGST | E56: SGST

Sheet LEKHAMBHA- Member coll
A1: Sun Realty
A4: CALCULATION For the month ofJUN-25
A6: FLATE MEMBERS COLLECTION @ 5%
A7: Flat No. | B7: Name of Owner | C7: CR SIDE | D7: Receipt of Registration Fees/JV (Cr) | E7: Payment of Reg Fees on Behalf of Client / JV (Dr) | F7: Receipt of Stamp Duty/JV (Cr) | G7: Payment of Stamp Duty/JV (Cr) | J7: REFUND OF SAME PEROID | K7: REFUND WITHOUT GST | L7: AEC,AUDA JV | M7: NET RECEIPT
H8: cheque return | I8: cancellation of plot
E9: =D9 | G9: =F9 | L9: 0 | M9: =C9-D9-F9 | N9: =M9*2.5%
M10: =C10-D10-F10 | N10: =M10*2.5%
M11: =C11-D11-F11 | N11: =M11*2.5%
M12: =C12-D12-F12 | N12: =M12*2.5%
M13: =C13-D13-F13 | N13: =M13*2.5%
M14: =C14-D14-F14-H14 | N14: =M14*2.5%
M15: =C15-D15-F15-H15 | N15: =M15*2.5%
M16: =C16-D16-F16-H16-I16 | N16: =M16*2.5%
M17: =C17-D17-F17-H17 | N17: =M17*2.5%
M18: =C18-D18-F18-H18 | N18: =M18*2.5%
M19: =C19-D19-F19-H19 | N19: =M19*2.5%
M20: =C20-D20-F20-H20 | N20: =M20*2.5%
M21: =C21-D21-F21-H21 | N21: =M21*2.5%
M22: =C22-D22-F22-H22 | N22: =M22*2.5%
M23: =C23-D23-F23-H23 | N23: =M23*2.5%
M24: =C24-D24-F24-H24 | N24: =M24*2.5%
M25: =C25-D25-F25-H25 | N25: =M25*2.5%
M26: =C26-D26-F26-H26 | N26: =M26*2.5%
M27: =C27-D27-F27-H27 | N27: =M27*2.5%
M28: =C28-D28-F28-H28 | N28: =M28*2.5%
M29: =C29-D29-F29-H29 | N29: =M29*2.5%
E30: =+D30 | G30: =+F30 | M30: =C30-D30-F30-H30 | N30: =M30*2.5%
A32: Total | C32: =SUM(C9:C30) | D32: =SUM(D9:D30) | E32: =SUM(E9:E30) | F32: =SUM(F9:F30) | G32: =SUM(G9:G30) | J32: =SUM(J9:J30) | K32: =SUM(K9:K30) | L32: =SUM(L9:L30) | M32: =SUM(M9:M30)
A35: SHOP MEMBERS COLLECTION
A36: Flat No. | B36: Name of Owner | C36: CR SIDE | D36: Receipt of Registration Fees | E36: Payment of Reg Fees on Behalf of Client | F36: Receipt of Stamp Duty/JV (Cr) | G36: Payment of Stamp Duty/JV (Cr) | J36: REFUND OF SAME PEROID | K36: REFUND WITHOUT GST | L36: AEC,AUDA JV | M36: NET RECEIPT
E38: =D38 | G38: =F38 | M38: =C38-D38-F38
E39: =D39 | G39: =F39 | M39: =C39-D39-F39 | N39: =M39*2.5/100
E40: =D40 | G40: =F40 | M40: =C40-D40-F40 | N40: =M40*2.5/100
E41: =+D41 | M41: =C41-D41-F41 | N41: =M41*2.5/100
E42: =+D42 | M42: =C42-D42-F42 | N42: =M42*2.5/100
E43: =+D43 | M43: =C43-D43-F43 | N43: =M43*2.5/100
E44: =+D44 | M44: =C44-D44 | N44: =M44*2.5/100
A45: Total | C45: =SUM(C38:C44) | D45: =SUM(D38:D44) | E45: =SUM(E38:E44) | J45: =SUM(J38:J44) | K45: =SUM(K38:K44) | L45: =SUM(L38:L44) | M45: =SUM(M38:M44)

Sheet LEKHAMBHA
A1: Sun Realty -LEKHAMBHA
A2: GST PAYABLE ON COMMERCIAL CONSTRUCTION FOR THE MONTH OFJUN-25
A4: Supply | B4: AMOUNT | C4: RATE | D4: CGST | E4: SGST | F4: TOTAL
A6: SUN REALTY -SUN SILVER SPRINGS RESIDENTIAL | B6: ='LEKHAMBHA- Member coll'!M32 | C6: 0.05 | D6: =B6*C6/2 | E6: =B6*C6/2 | F6: =+D6+E6
A7: Less : Refund | B7: =-'LEKHAMBHA- Member coll'!J32 | C7: 0.05 | D7: =B7*C7/2 | E7: =B7*C7/2 | F7: =+D7+E7
A9: SUN REALTY -SUN SILVER SPRINGS COMMERCIAL | B9: =+'LEKHAMBHA- Member coll'!M45 | C9: 0.05 | D9: =B9*C9/2 | E9: =B9*C9/2 | F9: =+D9+E9
A10: Less : Refund | B10: =+'LEKHAMBHA- Member coll'!J45 | C10: 0.05 | D10: =B10*C10/2 | E10: =B10*C10/2 | F10: =+D10+E10
A13: TOTAL | B13: =SUM(B6:B11) | D13: =SUM(D6:D12) | E13: =SUM(E6:E12) | F13: =SUM(F6:F12)
A15: GST PAYABLE UNDER RCM FOR THE MONTH OFJUN-25
A16: .
A17: Service | B17: AMOUNT | C17: RATE | D17: CGST | E17: SGST | F17: TOTAL
A19: SUN REALTY -SUN SILVER SPRINGS
A20: Advocate fees | B20: 0 | C20: 0.18 | D20: =+B20*9/100 | E20: =+D20 | F20: =+D20+E20
A21: Carting and Transportation (Gayatri Sales Corp)/ ASHOK P VANJARA | B21: 0 | C21: 0.05 | D21: =+B21*0.025 | E21: =+D21 | F21: =+D21+E21
A22: Security Services | B22: 0 | C22: 0.18 | D22: =+B22*9% | E22: =+B22*9% | F22: =SUM(D22:E22)
A23: Sponsorship Exp | C23: 0.18 | D23: =+B23*9% | E23: =+B23*9% | F23: =SUM(D23:E23)
A24: Royalty Exp. | C24: 0.18 | D24: =+B24*9% | E24: =+B24*9% | F24: =SUM(D24:E24)
A25: TOTAL | B25: =SUM(B19:B24) | D25: =SUM(D19:D24) | E25: =SUM(E19:E24) | F25: =SUM(F19:F24)
A27: INELIGIBLE CREDIT FOR THE MONTH OFJUN-25
A29: PARTICULARS | B29: CGST | C29: SGST | D29: IGST
A31: ITC FOR THEJUN-25 | B31: 0 | C31: =+B31 | D31: 0
A32: Direct Exp. | B32: 0 | C32: =+B32
A33: Indirect Exp. | B33: 0 | C33: =+B33
A34: Add: Ineligible ITC (whole year adjustment) | C34: =+B34
A35: Add: Ineligible ITC FOR RCM | B35: =+D25 | C35: =+E25
A36: Total ineligible CENVAYT | B36: =SUM(B31:B35) | C36: =SUM(C31:C35) | D36: =SUM(D31:D31)
A37: TOTAL | B37: =SUM(B36:B36) | C37: =SUM(C36:C36) | D37: =SUM(D36:D36)
A40: GST Payable for the month ofJUN-25
A42: PARTICULARS | B42: CGST | C42: SGST | D42: TOTAL
A44: =+A6 | B44: =+D13 | C44: =+E13 | D44: =+F13
A46: TOTAL PAYABLE FOR RESIDENTIAL INCLUDING IGST | B46: =+B44+B45 | C46: =+C44+C45 | D46: =+D44+D45
A48: GST UNDER RCM
B49: =+D25 | C49: =B49 | D49: =+B49+C49
A50: SUN OFFICE | D50: =+B50+C50
A51: GST Payable | B51: =+B46+B49+B50 | C51: =+C46+C49+C50 | D51: =+D46+D49+D50
A52: Net GST Payable | B52: =+B51 | C52: =+C51 | D52: =+D51

Sheet FINAL CALC
A3: Sun Realty
A4: GST PAYABLE ON COMMERCIAL CONSTRUCTION FOR THE MONTH OF AUG-26
A6: Supply | B6: AMOUNT | C6: LAND VALUE (1/3) | D6: TAXABLE VALUE (2/3) | E6: RATE | F6: CGST | G6: SGST | H6: TOTAL
A8: SUN GRAVITAS advance | B8: =+'SUN REALTY-CALC'!B19 | C8: =+'SUN REALTY-CALC'!C19 | D8: =+'SUN REALTY-CALC'!D19 | E8: 0.18 | F8: =+'SUN REALTY-CALC'!F19 | G8: =+'SUN REALTY-CALC'!G19 | H8: =+'SUN REALTY-CALC'!H19
A9: SUN GRAVITAS Payable due to Adjustment of Advances against Sale Deed Executed | B9: ='SUN REALTY-CALC'!B12 | D9: =+'SUN REALTY-CALC'!D16 | E9: 0.18 | F9: =+'SUN REALTY-CALC'!F12 | G9: =+F9 | H9: =+F9+G9
A10: SUN GRAVITAS Exempt Income | B10: =+'SUN REALTY-CALC'!B26+'SUN REALTY-CALC'!B27
A11: Extra work Income (B2C) | B11: =+'SUN REALTY-CALC'!D24 | D11: =+B11 | E11: 0.18 | F11: =+'SUN REALTY-CALC'!F24 | G11: =+F11 | H11: =+F11+G11
A12: Advance adjusted for same | B12: =+'SUN REALTY-CALC'!D25 | D12: =+B12 | E12: 0.18 | F12: =+'SUN REALTY-CALC'!F25 | G12: =+F12 | H12: =+F12+G12
A13: Cancellation Charges Income (B2C) | B13: =+'SUN REALTY-CALC'!D21 | D13: =+'SUN REALTY-CALC'!D22 | E13: 0.18 | F13: =D13*E13/2 | G13: =+F13 | H13: =+F13+G13 | XFD13: =+'SUN REALTY-CALC'!XFD28
A14: Advance adjusted for same | B14: =+'SUN REALTY-CALC'!D23 | D14: =+B14 | E14: 0.18 | F14: =D14*E14/2 | G14: =+F14 | H14: =+F14+G14
A16: SUN REALTY ATMOSPHERE RESIDENTIAL | B16: =+'SUN REALTY ATMOS-CALC'!B15 | D16: =+B16 | E16: 0.01 | F16: =D16*E16/2 | G16: =+F16 | H16: =G16+F16
A17: SUN REALTY ATMOSPHERE RESIDENTIAL More Than 5% | B17: =+'SUN REALTY ATMOS-CALC'!B24 | D17: =B17 | E17: 0.05 | F17: =D17*E17/2 | G17: =+F17 | H17: =G17+F17
A18: SUN REALTY ATMOSPHERE COMMERCIAL | B18: =+'SUN REALTY ATMOS-CALC'!B30 | D18: =+'SUN REALTY ATMOS-CALC'!B26+'SUN REALTY ATMOS-CALC'!B27 | E18: 0.05 | F18: =D18*E18/2 | G18: =+F18 | H18: =G18+F18
A19: SUN REALTY ATMOSPHERE COMMERCIAL PLC | B19: =+'SUN REALTY ATMOS-CALC'!B25+'SUN REALTY ATMOS-CALC'!B20 | D19: =+B19 | E19: 0.18 | F19: =D19*E19/2 | G19: =+F19 | H19: =G19+F19
A20: Cancellation Charges Income (B2C) | B20: 0 | D20: =B20 | E20: 0.18 | F20: =D20*E20/2 | G20: =+F20 | H20: =G20+F20
A21: SUN Atmoshphere Exempt Income | B21: =+'SUN REALTY ATMOS-CALC'!B34
A23: SUN REALTY FOOTPRINT RESIDENTIAL | B23: =+'FOOTPRINT- CALCULATION'!B6+'FOOTPRINT- CALCULATION'!B7+'FOOTPRINT- CALCULATION'!B8 | D23: =B23 | E23: 0.01 | F23: =B23*E23/2 | G23: =+F23 | H23: =G23+F23
A24: SUN REALTY FOOTPRINT COMMERCIAL | B24: ='FOOTPRINT- CALCULATION'!B11+'FOOTPRINT- CALCULATION'!B12 | D24: =B24 | E24: 0.05 | F24: ='FOOTPRINT- CALCULATION'!D11+'FOOTPRINT- CALCULATION'!D12 | G24: =+F24 | H24: =G24+F24
A25: Cancellation Charges Income (B2C) | B25: =+D25 | D25: =+'FOOTPRINT- CALCULATION'!B16 | E25: 0.18 | F25: =D25*E25/2 | G25: =+'FOOTPRINT- CALCULATION'!E16 | H25: =+'FOOTPRINT- CALCULATION'!F16
A26: SUN Footprint Exempt Income | B26: =+'FOOTPRINT- CALCULATION'!B17
A28: SUN REALTY - SUN PARK WEST RESIDENTIAL | B28: =+'SUN PARK WEST'!B6+'SUN PARK WEST'!B8+'SUN PARK WEST'!B9+'SUN PARK WEST'!B7 | D28: =B28 | E28: 0.01 | F28: =D28*E28/2 | G28: =+F28 | H28: =+G28+F28
A29: SUN REALTY - SUN PARK WEST RESIDENTIAL More than 45 lacs | B29: =+'SUN PARK WEST'!B10+'SUN PARK WEST'!B12+'SUN PARK WEST'!B11 | D29: =+B29 | E29: 0.05 | F29: =D29*E29/2 | G29: =+F29 | H29: =+G29+F29
A30: SUN REALTY -SUN PARK WEST COMMERCIAL | B30: =+'SUN PARK WEST'!B14+'SUN PARK WEST'!B15 | D30: =+B30 | E30: 0.05 | F30: =D30*E30/2 | G30: =+F30 | H30: =+G30+F30
A32: SUN REALTY -SUN SILVER SPRINGS RESIDENTIAL | B32: =+'SUN SILVER SPRING'!B7+'SUN SILVER SPRING'!B8+'SUN SILVER SPRING'!B9 | D32: =+B32 | E32: 0.05 | F32: =D32*E32/2 | G32: =+F32 | H32: =+G32+F32
A33: SUN REALTY -SUN SILVER SPRINGS COMMERCIAL | B33: =+'SUN SILVER SPRING'!B11+'SUN SILVER SPRING'!B12 | D33: =+B33 | E33: 0.05 | F33: =D33*E33/2 | G33: =+F33 | H33: =+G33+F33
A35: TOTAL | B35: =SUM(B8:B33) | C35: =SUM(C8:C33) | D35: =SUM(D8:D33) | E35: =E8+E16+E18+E24+E23 | F35: =SUM(F8:F33) | G35: =SUM(G8:G33) | H35: =SUM(H8:H33)
B36: TAXABLE VALUE (2/3) | C36: CGST | D36: SGST
A37: 0.18 | B37: =+D8+D9+D19 | C37: =B37*A37/2 | D37: =+C37
A38: 0.01 | B38: =+D16+D23+D28 | C38: =B38*A38/2 | D38: =+C38
A39: 0.05 | B39: =+D17+D18+D24+D29+D30+D32+D33 | C39: =B39*A39/2 | D39: =+C39
A40: 18%(DIRECT B2C) | B40: =+D11+D13+D25 | C40: =+F11+F13+F25 | D40: =+G11+G13+G25
A41: Non GST income | B41: =+C8
A42: exempt income | B42: =+B10+B21+B26
A45: Supply | B45: GSTIN | D45: AMOUNT | E45: RATE | F45: CGST | G45: SGST | H45: TOTAL
A48: Rent income-Meglyn Technologies Pvt Ltd (SAC-)] ( To be Confirm is there any income )-997212 | B48: 24AAJCM9952F1Z6 | D48: =+'SUN REALTY-CALC'!D38 | E48: 0.18 | F48: =+D48*E48/2 | G48: =+D48*E48/2 | H48: =+SUM(F48:G48)
D50: =+SUM(D47:D49) | F50: =+SUM(F47:F49) | G50: =+SUM(G47:G49) | H50: =+SUM(H47:H49)
A52: GST PAYABLE UNDER RCM FOR THE MONTH OF AUG-26
A53: .
A54: Service | B54: AMOUNT | C54: RATE | D54: CGST | E54: SGST | F54: TOTAL
A56: SUN GRAVITAS | B56: ='SUN REALTY-CALC'!B55 | D56: ='SUN REALTY-CALC'!D55 | E56: ='SUN REALTY-CALC'!E55 | F56: ='SUN REALTY-CALC'!F55
...

Sheet ENTRIES-SUN REALTY
A2: MONTHLY ENTRIES FOR M/s. SUN REALTY-GRAVITAS
A3: 46265
A5: Sr. No. | B5: Date | C5: Particulars | D5: Amt(Rs.) | E5: Amt(Rs.)
D6: Dr. | E6: Cr.
A8: 1 | B8: 46265 | C8: CGST on collection A/c Dr | D8: =+'FINAL CALC'!B104
C9: SGST on collection A/c Dr | D9: =+D8
C10: To CGST payable A/c | E10: =+D8
C11: To SGST payable A/c | E11: =+D9
C12: (Being gst collected transferred to gst payable
C13: for the month of Apr-26)
A15: 2 | B15: =+B8 | C15: CGST Receivable RCM A/c Dr | D15: ='SUN REALTY-CALC'!D55
C16: SGST Receivable RCM A/c Dr | D16: ='SUN REALTY-CALC'!E55
C17: To CGST payable A/c | E17: =+D15
C18: To SGST payable A/c | E18: =+D16
C19: (Being GST payable under RCM transferred to
C20: GST payabel A/C for the month of Apr-26)
A22: 3 | B22: =+B15 | C22: CGST Receivable A/c Dr | D22: ='FINAL CALC'!B120
C23: SGST Receivable A/c Dr | D23: ='FINAL CALC'!C120
C24: To CGST Receivable RCM A/c | E24: =D22
C25: To SGST Receivable RCM A/c | E25: =D23
